<robot name="robot">
  <link name="base_footprint"></link>
  <joint name="base_joint" type="fixed">
    <parent link="base_footprint" />
    <child link="base_link" />
    <origin xyz="0 0 0.1039766581471834" rpy="0 0 0" />
  </joint>
  <link name="base_link">
    <visual>
      <origin xyz="0 0 0" rpy="0 0 0" />
      <geometry>
        <box size="1 1 0.2" />
      </geometry>
      <material name="base_link-material">
        <color rgba="0.16202937562896222 0.450785782828426 0.02028856305209031 1" />
      </material>
    </visual>
    <collision>
      <origin xyz="0 0 0" rpy="0 0 0" />
      <geometry>
        <box size="1 1 0.2" />
      </geometry>
    </collision>
    <inertial>
      <origin xyz="0 0 0" rpy="0 0 0" />
      <mass value="10" />
      <inertia ixx="1.6666666666666665" ixy="0" ixz="0" iyy="1.6666666666666665" iyz="0" izz="1.6666666666666665" />
    </inertial>
  </link>
  <joint name="base_link_to_arm_1" type="continuous">
    <parent link="base_link" />
    <child link="arm_1" />
    <origin xyz="0 0 0.1" rpy="0 0 0" />
    <axis xyz="0 0 1"/>
  </joint>
  <link name="arm_1">
    <visual>
      <origin xyz="0 0 0.75" rpy="0 0 0" />
      <geometry>
        <box size="0.05 0.1 1.5" />
      </geometry>
      <material name="arm_1-material">
        <color rgba="0.8468732315065057 0.033104766565152086 0.04373502925049377 1" />
      </material>
    </visual>
    <collision>
      <origin xyz="0 0 0.75" rpy="0 0 0" />
      <geometry>
        <box size="0.05 0.1 1.5" />
      </geometry>
    </collision>
    <inertial>
      <origin xyz="0 0 0.75" rpy="0 0 0" />
      <mass value="2" />
      <inertia ixx="0.3333333333333333" ixy="0" ixz="0" iyy="0.3333333333333333" iyz="0" izz="0.3333333333333333" />
    </inertial>
  </link>
  <joint name="arm_1_to_arm_2" type="revolute">
    <parent link="arm_1" />
    <child link="arm_2" />
    <origin xyz="0 0 1.5" rpy="1.5707963267948966 2.220446049250313e-16 1.5707963267948963" />
    <axis xyz="0 0 1"/>
    <limit effort="1000.0" lower="0" upper="2" velocity="0.5"/>  </joint>
  <link name="arm_2">
    <visual>
      <origin xyz="0 0.5 0.05" rpy="0 0 0" />
      <geometry>
        <box size="0.1 1 0.05" />
      </geometry>
      <material name="arm_2-material">
        <color rgba="0.035601314869097636 0.23074004851362043 0.775822218312646 1" />
      </material>
    </visual>
    <collision>
      <origin xyz="0 0.5 0.05" rpy="0 0 0" />
      <geometry>
        <box size="0.1 1 0.05" />
      </geometry>
    </collision>
    <inertial>
      <origin xyz="0 0.5 0.05" rpy="0 0 0" />
      <mass value="1" />
      <inertia ixx="0.16666666666666666" ixy="0" ixz="0" iyy="0.16666666666666666" iyz="0" izz="0.16666666666666666" />
    </inertial>
  </link>
  <joint name="arm_2_to_arm_3" type="revolute">
    <parent link="arm_2" />
    <child link="arm_3" />
    <origin xyz="0 1 0" rpy="0 0 0" />
    <axis xyz="0 0 1"/>
    <limit effort="1000.0" lower="-1" upper="1" velocity="0.5"/>  </joint>
  <link name="arm_3">
    <visual>
      <origin xyz="0 0.3 0" rpy="0 0 0" />
      <geometry>
        <box size="0.1 0.6 0.05" />
      </geometry>
      <material name="arm_3-material">
        <color rgba="0.5647115056965487 0.015208514418949472 0.6653872982754769 1" />
      </material>
    </visual>
    <collision>
      <origin xyz="0 0.3 0" rpy="0 0 0" />
      <geometry>
        <box size="0.1 0.6 0.05" />
      </geometry>
    </collision>
    <inertial>
      <origin xyz="0 0.3 0" rpy="0 0 0" />
      <mass value="1" />
      <inertia ixx="0.16666666666666666" ixy="0" ixz="0" iyy="0.16666666666666666" iyz="0" izz="0.16666666666666666" />
    </inertial>
  </link>
  <joint name="arm_3_to_gripper_base" type="revolute">
    <parent link="arm_3" />
    <child link="gripper_base" />
    <origin xyz="0 0.625 0" rpy="-0.7853981633974483 1.5707963267948966 0.7853981633974483" />
    <axis xyz="0 0 1"/>
    <limit effort="1000.0" lower="-1" upper="1" velocity="0.5"/>  </joint>
  <link name="gripper_base">
    <visual>
      <origin xyz="0 0 0" rpy="0 0 0" />
      <geometry>
        <box size="0.3 0.1 0.05" />
      </geometry>
      <material name="gripper_base-material">
        <color rgba="0.030713443727452196 0.04231141061442144 0.24620132669705552 1" />
      </material>
    </visual>
    <collision>
      <origin xyz="0 0 0" rpy="0 0 0" />
      <geometry>
        <box size="0.3 0.1 0.05" />
      </geometry>
    </collision>
    <inertial>
      <origin xyz="0 0 0" rpy="0 0 0" />
      <mass value="1" />
      <inertia ixx="0.16666666666666666" ixy="0" ixz="0" iyy="0.16666666666666666" iyz="0" izz="0.16666666666666666" />
    </inertial>
  </link>
  <joint name="gripper_base_to_finger_left" type="prismatic">
    <parent link="gripper_base" />
    <child link="finger_left" />
    <origin xyz="0.175 0 0.125" rpy="0 -1.5707963267948966 0" />
    <axis xyz="0 0 1"/>
    <limit effort="1000.0" lower="0" upper="0.15" velocity="0.5"/>  </joint>
  <link name="finger_left">
    <visual>
      <origin xyz="0 0 0" rpy="0 0 0" />
      <geometry>
        <box size="0.2 0.1 0.05" />
      </geometry>
      <material name="finger_left-material">
        <color rgba="0.012983032338510335 0.5583403896257968 0.4396571738310091 1" />
      </material>
    </visual>
    <collision>
      <origin xyz="0 0 0" rpy="0 0 0" />
      <geometry>
        <box size="0.2 0.1 0.05" />
      </geometry>
    </collision>
    <inertial>
      <origin xyz="0 0 0" rpy="0 0 0" />
      <mass value="0.2" />
      <inertia ixx="0.03333333333333333" ixy="0" ixz="0" iyy="0.03333333333333333" iyz="0" izz="0.03333333333333333" />
    </inertial>
  </link>
  <joint name="gripper_base_to_finger_right" type="prismatic">
    <parent link="gripper_base" />
    <child link="finger_right" />
    <origin xyz="-0.175 0 0.125" rpy="0 -1.5707963267948966 0" />
    <axis xyz="0 0 1"/>
    <limit effort="1000.0" lower="-0.15" upper="0" velocity="0.5"/>  </joint>
  <link name="finger_right">
    <visual>
      <origin xyz="0 0 0" rpy="0 0 0" />
      <geometry>
        <box size="0.2 0.1 0.05" />
      </geometry>
      <material name="finger_right-material">
        <color rgba="0.9215818562755338 0.6514056374127929 0.026241221889696346 1" />
      </material>
    </visual>
    <collision>
      <origin xyz="0 0 0" rpy="0 0 0" />
      <geometry>
        <box size="0.2 0.1 0.05" />
      </geometry>
    </collision>
    <inertial>
      <origin xyz="0 0 0" rpy="0 0 0" />
      <mass value="0.2" />
      <inertia ixx="0.03333333333333333" ixy="0" ixz="0" iyy="0.03333333333333333" iyz="0" izz="0.03333333333333333" />
    </inertial>
  </link>
</robot>